Workbook

Sheet Executive Dashboard
A1: Executive Dashboard
A3: Program KPI | B3: Target / Count | D3: Month | E3: Apps This Month | F3: Cumulative Apps | G3: Planned Status
A4: Applications in Scope | B4: 20 | D4: M1 | E4: 0 | F4: 0 | G4: Green
A5: Roadmap Records | B5: 107 | D5: M2 | E5: 3 | F5: 3 | G5: Green
A6: Program Duration (Weeks) | B6: 26 | D6: M3 | E6: 5 | F6: 8 | G6: Green
A7: Apps Planned by M5 | B7: 20 | D7: M4 | E7: 6 | F7: 14 | G7: Amber
A8: Availability Target | B8: 99.95% | D8: M5 | E8: 6 | F8: 20 | G8: Amber
A9: RPO Target | B9: <= 5 min | D9: M6 | E9: 0 | F9: 20 | G9: Green
A10: RTO Target | B10: <= 60 min | D10: M6 | E10: 0 | F10: 20 | G10: Green
A11: Legacy Platforms to Retire | B11: 2 | D11: M6 | E11: 0 | F11: 20 | G11: Green
A14: Health Measure | B14: Current
A15: Critical-path records | B15: =COUNTIF('Detailed Monthly Tracker'!P:P,"Yes") -> 43
A16: Tasks Complete | B16: =COUNTIF('Detailed Monthly Tracker'!R:R,"Complete") -> 0
A17: Tasks In Progress | B17: =COUNTIF('Detailed Monthly Tracker'!R:R,"In Progress") -> 0
A18: Tasks Blocked | B18: =COUNTIF('Detailed Monthly Tracker'!R:R,"Blocked") -> 0
A19: Tasks At Risk | B19: =COUNTIF('Detailed Monthly Tracker'!V:V,"Amber")+COUNTIF('Detailed Monthly Tracker'!V:V,"Red") -> 0
A20: Apps Complete | B20: =COUNTIF('Application Tracker'!O:O,"Complete") -> 0
A21: Apps Ready for Cutover | B21: =COUNTIF('Application Tracker'!O:O,"Ready for Cutover") -> 0
A22: Dependencies Red | B22: =COUNTIF('Critical Dependencies'!P:P,"Red") -> 5
A23: Top Risks Red | B23: =COUNTIF('RAID Register'!G:G,"Red") -> 8
A24: Gates Ready | B24: =COUNTIF('Gate Readiness'!I4:I15,"Green") -> 0

Sheet Executive Roadmap
A1: Legacy to GCP Migration - Executive Roadmap
A2: 20 applications | 26 weeks
A4: Month | B4: Weeks | C4: Executive Milestone | D4: Primary Outcomes | E4: Apps This Month | F4: Cumulative Apps | G4: Approval Gate | H4: Gate Owner | I4: Planned Status
A5: M1 | B5: W1-W4 | C5: Foundation Ready | D5: Discovery, dependency map, wave plan, landing zone, security sign-off, replication path | E5: 0 | F5: 0 | G5: GATE-M1 | H5: Security + Platform | I5: Green
A6: M2 | B6: W5-W9 | C6: Pilot Proven | D6: 3 pilot apps, rehearsed rollback, production cutover, hypercare, SLO and DR validation | E6: 3 | F6: 3 | G6: GATE-M2 | H6: Steering Committee | I6: Green
A7: M3 | B7: W10-W13 | C7: Wave 1 Complete | D7: 5 low-complexity apps, DB migration, production cutover, hypercare and DR test | E7: 5 | F7: 8 | G7: GATE-M3 | H7: Steering Committee | I7: Green
A8: M4 | B8: W14-W17 | C8: Wave 2 Complete | D8: 6 complex/shared-DB apps, split cutovers 2a/2b, hypercare and shared-DB DR test | E8: 6 | F8: 14 | G8: GATE-M4 | H8: Steering Committee | I8: Amber
A9: M5 | B9: W18-W21 | C9: Wave 3 Complete | D9: 6 remaining/Tier-1 apps, split cutovers 3a/3b, peak-load test, hypercare and DR test | E9: 6 | F9: 20 | G9: GATE-M5 | H9: Steering Committee | I9: Amber
A10: M6 | B10: W22-W26 | C10: Migration Complete | D10: Portfolio DR, SLO certification, SRE acceptance, archival, compliance and legacy decommission | E10: 0 | F10: 20 | G10: GATE-M6 | H10: Executive Sponsor / SteerCo | I10: Green

Sheet Detailed Monthly Tracker
A1: Detailed Monthly Tracker
A3: Month | B3: Phase | C3: Task ID | D3: Workstream | E3: Task / Milestone | F3: Owner | G3: Type | H3: Start Wk | I3: Duration | J3: End Wk | K3: Planned Start | L3: Planned Finish | M3: Predecessors | N3: Driving Pred. | O3: Link Type | P3: Critical Path | Q3: Freeze Check | R3: Status | S3: Deliverable / Evidence | T3: % Complete | U3: TPM Notes / Next Action | V3: RAG | W3: Actual Start | X3: Forecast Finish | Y3: Actual Finish | Z3: Schedule Variance (Days) | AA3: Recovery Plan
A4: M1 | B4: PROGRAM MANAGEMENT & GOVERNANCE | C4: PM-01 | D4: Program Management | E4: Program kickoff, charter, governance and decision rights | F4: TPM | G4: Task | H4: 1 | I4: 1 | J4: 1 | K4: 46307 | L4: 46311 | P4: No | R4: Not Started | S4: Charter; SteerCo terms of reference | T4: 0 | V4: Grey
A5: M1 | B5: PROGRAM MANAGEMENT & GOVERNANCE | C5: PM-02 | D5: Program Management | E5: Stand up RAID log, dependency dashboard and executive dashboard | F5: TPM | G5: Task | H5: 1 | I5: 2 | J5: 2 | K5: 46307 | L5: 46318 | M5: PM-01 | N5: PM-01 | O5: FS | P5: No | R5: Not Started | S5: RAID log (system of record); dashboards live | T5: 0 | V5: Grey | Z5: =IF(Y5<>"",Y5-L5,IF(X5<>"",X5-L5,""))
A6: M1 | B6: PROGRAM MANAGEMENT & GOVERNANCE | C6: PM-03 | D6: Program Management | E6: Baseline integrated plan, RACI, resource onboarding and SME backfill | F6: TPM | G6: Task | H6: 1 | I6: 2 | J6: 2 | K6: 46307 | L6: 46318 | M6: PM-01 | N6: PM-01 | O6: FS | P6: No | R6: Not Started | S6: Baselined plan; backfill approved | T6: 0 | V6: Grey | Z6: =IF(Y6<>"",Y6-L6,IF(X6<>"",X6-L6,""))
A7: M1 | B7: PROGRAM MANAGEMENT & GOVERNANCE | C7: PM-04 | D7: Program Management | E7: Agree change calendar: CAB slots, freeze windows, cutover windows | F7: TPM / Change Manager | G7: Task | H7: 1 | I7: 2 | J7: 2 | K7: 46307 | L7: 46318 | M7: PM-01 | N7: PM-01 | O7: FS | P7: No | R7: Not Started | S7: Published change & freeze calendar | T7: 0 | V7: Grey | Z7: =IF(Y7<>"",Y7-L7,IF(X7<>"",X7-L7,""))
A8: M1 | B8: PROGRAM MANAGEMENT & GOVERNANCE | C8: PM-05 | D8: Program Management | E8: Regulatory and third-party notification plan (cloud outsourcing, vendor risk) | F8: TPM / Compliance | G8: Task | H8: 2 | I8: 3 | J8: 4 | K8: 46314 | L8: 46332 | M8: PM-01 | N8: PM-01 | O8: FS | P8: No | R8: Not Started | S8: Regulatory engagement plan; notification dates | T8: 0 | V8: Grey | Z8: =IF(Y8<>"",Y8-L8,IF(X8<>"",X8-L8,""))
A9: M1-M6 | B9: PROGRAM MANAGEMENT & GOVERNANCE | C9: PM-06 | D9: Program Management | E9: Weekly SteerCo, Dependency Review Board and RAID review (recurring) | F9: TPM | G9: Task | H9: 2 | I9: 25 | J9: 26 | K9: 46314 | L9: 46486 | M9: PM-02 | N9: PM-02 | O9: FS | P9: No | R9: Not Started | S9: Weekly status report; decision log | T9: 0 | V9: Grey | Z9: =IF(Y9<>"",Y9-L9,IF(X9<>"",X9-L9,""))
A10: M1-M6 | B10: PROGRAM MANAGEMENT & GOVERNANCE | C10: PM-07 | D10: Program Management | E10: Monthly executive reporting, budget and cloud-spend vs forecast | F10: TPM / Finance | G10: Task | H10: 4 | I10: 23 | J10: 26 | K10: 46328 | L10: 46486 | M10: PM-02 | N10: PM-02 | O10: FS | P10: No | R10: Not Started | S10: Monthly exec pack | T10: 0 | V10: Grey | Z10: =IF(Y10<>"",Y10-L10,IF(X10<>"",X10-L10,""))
A11: M1-M6 | B11: PROGRAM MANAGEMENT & GOVERNANCE | C11: PM-08 | D11: Business Readiness | E11: Business readiness: comms plan, training, runbooks / SOPs (recurring) | F11: Change Manager | G11: Task | H11: 3 | I11: 22 | J11: 24 | K11: 46321 | L11: 46472 | M11: PM-03 | N11: PM-03 | O11: FS | P11: No | R11: Not Started | S11: Comms calendar; training records; SOPs | T11: 0 | V11: Grey | Z11: =IF(Y11<>"",Y11-L11,IF(X11<>"",X11-L11,""))
A12: M6 | B12: PROGRAM MANAGEMENT & GOVERNANCE | C12: PM-09 | D12: Program Management | E12: Program closure, final report and lessons learned | F12: TPM | G12: Task | H12: 26 | I12: 1 | J12: 26 | K12: 46482 | L12: 46486 | M12: GATE-M6 | N12: GATE-M6 | O12: FS | P12: No | R12: Not Started | S12: Closure report; RAID closed | T12: 0 | V12: Grey | Z12: =IF(Y12<>"",Y12-L12,IF(X12<>"",X12-L12,""))
A13: M1 | B13: DISCOVERY & PLANNING | C13: DS-01 | D13: Application Migration | E13: Application inventory and CMDB reconciliation (owners, tiers, criticality) | F13: App Teams / TPM | G13: Task | H13: 1 | I13: 2 | J13: 2 | K13: 46307 | L13: 46318 | M13: PM-01 | N13: PM-01 | O13: FS | P13: No | R13: Not Started | S13: Signed-off inventory of 20 apps | T13: 0 | V13: Grey | Z13: =IF(Y13<>"",Y13-L13,IF(X13<>"",X13-L13,""))
A14: M1 | B14: DISCOVERY & PLANNING | C14: DS-02 | D14: Application Migration | E14: Technical discovery workshops (runtime, config, secrets, integrations, batch schedules) | F14: Cloud Architects / App SMEs | G14: Task | H14: 1 | I14: 3 | J14: 3 | K14: 46307 | L14: 46325 | M14: DS-01 | N14: DS-01 | O14: SS | P14: No | R14: Not Started | S14: Per-app discovery pack | T14: 0 | V14: Grey | Z14: =IF(Y14<>"",Y14-L14,IF(X14<>"",X14-L14,""))
A15: M1 | B15: DISCOVERY & PLANNING | C15: DS-03 | D15: Program Management | E15: Dependency mapping: shared DBs, APIs, middleware, auth, file transfers, network flows | F15: TPM / Cloud Architects | G15: Task | H15: 2 | I15: 3 | J15: 4 | K15: 46314 | L15: 46332 | M15: DS-02 | N15: DS-02 | O15: SS | P15: No | R15: Not Started | S15: Dependency map; shared-DB groups | T15: 0 | V15: Grey | Z15: =IF(Y15<>"",Y15-L15,IF(X15<>"",X15-L15,""))
A16: M1 | B16: DISCOVERY & PLANNING | C16: DS-04 | D16: Database Migration | E16: Database inventory and profiling (size, version, extensions, growth, change rate) | F16: DBA Lead | G16: Task | H16: 1 | I16: 3 | J16: 3 | K16: 46307 | L16: 46325 | M16: DS-01 | N16: DS-01 | O16: SS | P16: No | R16: Not Started | S16: DB catalogue; compatibility findings | T16: 0 | V16: Grey | Z16: =IF(Y16<>"",Y16-L16,IF(X16<>"",X16-L16,""))
... A44: M2 | B44: PILOT WAVE (3 APPS: 1 .NET, 1 JAVA, 1 BATCH) | C44: GATE-PILOT | D44: Program Management | E44: PILOT GO-LIVE approval (approver: Steering Committee) + CAB | F44: Steering Committee | G44: Gate | H44: 6 | I44: 1 | J44: 6 | K44: 46342 | L44: 46346 | M44: PL-07 | N44: PL-07 | O44: FS | P44: Yes | R44: Not Started | S44: Go decision logged | T44: 0 | V44: Grey | Z44: =IF(Y44<>"",Y44-L44,IF(X44<>"",X44-L44,""))
A45: M2 | B45: PILOT WAVE (3 APPS: 1 .NET, 1 JAVA, 1 BATCH) | C45: PL-08 | D45: Cutover & Hypercare | E45: PILOT PRODUCTION CUTOVER (3 apps) | F45: SRE / App Teams | G45: Cutover | H45: 7 | I45: 1 | J45: 7 | K45: 46349 | L45: 46353 | M45: GATE-PILOT | N45: GATE-PILOT | O45: FS | P45: Yes | Q45: OK | R45: Not Started | S45: Pilot live in GCP | T45: 0 | V45: Grey | Z45: =IF(Y45<>"",Y45-L45,IF(X45<>"",X45-L45,""))
A46: M2 | B46: PILOT WAVE (3 APPS: 1 .NET, 1 JAVA, 1 BATCH) | C46: PL-09 | D46: Cutover & Hypercare | E46: Pilot hypercare (14+ days, 24x7 SRE support) | F46: SRE / App Teams | G46: Task | H46: 7 | I46: 3 | J46: 9 | K46: 46349 | L46: 46367 | M46: PL-08 | N46: PL-08 | O46: FS | P46: Yes | R46: Not Started | S46: Incident log; SLO data | T46: 0 | V46: Grey | Z46: =IF(Y46<>"",Y46-L46,IF(X46<>"",X46-L46,""))
A47: M2 | B47: PILOT WAVE (3 APPS: 1 .NET, 1 JAVA, 1 BATCH) | C47: PL-10 | D47: Cutover & Hypercare | E47: Pilot DR test: zone failure, regional failover, PITR restore (measure RPO / RTO) | F47: SRE / DBA | G47: DR Test | H47: 8 | I47: 1 | J47: 8 | K47: 46356 | L47: 46360 | M47: PL-08 | N47: PL-08 | O47: FS | P47: Yes | Q47: OK | R47: Not Started | S47: DR test report | T47: 0 | V47: Grey | Z47: =IF(Y47<>"",Y47-L47,IF(X47<>"",X47-L47,""))
A48: M2 | B48: PILOT WAVE (3 APPS: 1 .NET, 1 JAVA, 1 BATCH) | C48: PL-11 | D48: Program Management | E48: Pilot retrospective: update runbooks, tooling and wave estimates | F48: TPM | G48: Task | H48: 9 | I48: 1 | J48: 9 | K48: 46363 | L48: 46367 | M48: PL-09 | N48: PL-09 | O48: SS | P48: No | R48: Not Started | S48: Lessons learned; updated factory kit | T48: 0 | V48: Grey | Z48: =IF(Y48<>"",Y48-L48,IF(X48<>"",X48-L48,""))
A49: M2 | B49: PILOT WAVE (3 APPS: 1 .NET, 1 JAVA, 1 BATCH) | C49: GATE-M2 | D49: Program Management | E49: M2: PILOT PROVEN (SLOs, rollback, DR test, runbooks) | F49: Steering Committee | G49: Gate | H49: 9 | I49: 1 | J49: 9 | K49: 46363 | L49: 46367 | M49: PL-10, PL-11 | N49: PL-11 | O49: FS | P49: Yes | R49: Not Started | S49: Gate to scale to Wave 1-3 | T49: 0 | V49: Grey | Z49: =IF(Y49<>"",Y49-L49,IF(X49<>"",X49-L49,""))
A50: M1-M2 | B50: WAVE 1 (5 APPS - LOW COMPLEXITY, INDEPENDENT) | C50: W1-01 | D50: Application Migration | E50: Containerise, build pipelines and config for 5 Wave 1 apps | F50: App Teams | G50: Task | H50: 3 | I50: 3 | J50: 5 | K50: 46321 | L50: 46339 | M50: DS-05 | N50: DS-05 | O50: SS | P50: No | R50: Not Started | S50: Images and pipelines | T50: 0 | V50: Grey | Z50: =IF(Y50<>"",Y50-L50,IF(X50<>"",X50-L50,""))
A51: M2 | B51: WAVE 1 (5 APPS - LOW COMPLEXITY, INDEPENDENT) | C51: W1-02 | D51: Application Migration | E51: Deploy to GCP non-prod; integration endpoints; observability | F51: Platform / App Teams | G51: Task | H51: 5 | I51: 2 | J51: 6 | K51: 46335 | L51: 46346 | M51: W1-01, GATE-M1 | N51: W1-01 | O51: FS | P51: No | R51: Not Started | S51: Wave 1 in non-prod | T51: 0 | V51: Grey | Z51: =IF(Y51<>"",Y51-L51,IF(X51<>"",X51-L51,""))
A52: M2 | B52: WAVE 1 (5 APPS - LOW COMPLEXITY, INDEPENDENT) | C52: W1-03 | D52: Database Migration | E52: DB initial load and replication (5 DBs); lag monitoring | F52: DBA Lead | G52: Task | H52: 5 | I52: 3 | J52: 7 | K52: 46335 | L52: 46353 | M52: GATE-M1 | N52: GATE-M1 | O52: FS | P52: No | R52: Not Started | S52: Replicating DBs | T52: 0 | V52: Grey | Z52: =IF(Y52<>"",Y52-L52,IF(X52<>"",X52-L52,""))
A53: M2 | B53: WAVE 1 (5 APPS - LOW COMPLEXITY, INDEPENDENT) | C53: W1-04 | D53: Testing | E53: Functional, regression, performance and security testing | F53: QA Lead | G53: Task | H53: 6 | I53: 2 | J53: 7 | K53: 46342 | L53: 46353 | M53: W1-02 | N53: W1-02 | O53: FS | P53: No | R53: Not Started | S53: Test reports | T53: 0 | V53: Grey | Z53: =IF(Y53<>"",Y53-L53,IF(X53<>"",X53-L53,""))
A54: M2 | B54: WAVE 1 (5 APPS - LOW COMPLEXITY, INDEPENDENT) | C54: W1-05 | D54: Database Migration | E54: Data validation and reconciliation (counts, checksums) | F54: DBA Lead | G54: Task | H54: 7 | I54: 2 | J54: 8 | K54: 46349 | L54: 46360 | M54: W1-03 | N54: W1-03 | O54: FS | P54: No | R54: Not Started | S54: Reconciliation sign-off | T54: 0 | V54: Grey | Z54: =IF(Y54<>"",Y54-L54,IF(X54<>"",X54-L54,""))
A55: M2 | B55: WAVE 1 (5 APPS - LOW COMPLEXITY, INDEPENDENT) | C55: W1-06 | D55: Program Management | E55: Apply pilot lessons learned; finalise runbooks and rollback plan | F55: TPM / SRE | G55: Task | H55: 9 | I55: 1 | J55: 9 | K55: 46363 | L55: 46367 | M55: PL-11 | N55: PL-11 | O55: SS | P55: No | R55: Not Started | S55: Updated runbooks | T55: 0 | V55: Grey | Z55: =IF(Y55<>"",Y55-L55,IF(X55<>"",X55-L55,""))
A56: M2 | B56: WAVE 1 (5 APPS - LOW COMPLEXITY, INDEPENDENT) | C56: W1-07 | D56: Cutover & Hypercare | E56: Cutover rehearsal incl. rollback | F56: SRE Lead | G56: Task | H56: 8 | I56: 1 | J56: 8 | K56: 46356 | L56: 46360 | M56: W1-04 | N56: W1-04 | O56: FS | P56: Yes | R56: Not Started | S56: Rehearsal record | T56: 0 | V56: Grey | Z56: =IF(Y56<>"",Y56-L56,IF(X56<>"",X56-L56,""))
A57: M2 | B57: WAVE 1 (5 APPS - LOW COMPLEXITY, INDEPENDENT) | C57: GATE-W1-GO | D57: Program Management | E57: WAVE 1 GO / NO-GO + CAB approval | F57: CAB | G57: Gate | H57: 9 | I57: 1 | J57: 9 | K57: 46363 | L57: 46367 | M57: W1-07, W1-05, W1-06, GATE-M2 | N57: W1-07 | O57: FS | P57: Yes | R57: Not Started | S57: Approved change request | T57: 0 | V57: Grey | Z57: =IF(Y57<>"",Y57-L57,IF(X57<>"",X57-L57,""))
A58: M3 | B58: WAVE 1 (5 APPS - LOW COMPLEXITY, INDEPENDENT) | C58: W1-08 | D58: Cutover & Hypercare | E58: WAVE 1 PRODUCTION CUTOVER (5 apps) - before year-end freeze | F58: SRE / App Teams | G58: Cutover | H58: 10 | I58: 1 | J58: 10 | K58: 46370 | L58: 46374 | M58: GATE-W1-GO, GATE-M2 | N58: GATE-W1-GO | O58: FS | P58: Yes | Q58: OK | R58: Not Started | S58: Wave 1 live in GCP | T58: 0 | V58: Grey | Z58: =IF(Y58<>"",Y58-L58,IF(X58<>"",X58-L58,""))
A59: M3 | B59: WAVE 1 (5 APPS - LOW COMPLEXITY, INDEPENDENT) | C59: W1-09 | D59: Cutover & Hypercare | E59: Wave 1 hypercare (runs through the freeze - no changes) | F59: SRE / App Teams | G59: Task | H59: 11 | I59: 3 | J59: 13 | K59: 46377 | L59: 46395 | M59: W1-08 | N59: W1-08 | O59: FS | P59: Yes | R59: Not Started | S59: Hypercare exit evidence | T59: 0 | V59: Grey | Z59: =IF(Y59<>"",Y59-L59,IF(X59<>"",X59-L59,""))
A60: M3 | B60: WAVE 1 (5 APPS - LOW COMPLEXITY, INDEPENDENT) | C60: W1-10 | D60: Cutover & Hypercare | E60: Wave 1 DR test (zone and regional failover) | F60: SRE / DBA | G60: DR Test | H60: 13 | I60: 1 | J60: 13 | K60: 46391 | L60: 46395 | M60: W1-09 | N60: W1-09 | O60: FS | P60: Yes | Q60: OK | R60: Not Started | S60: DR test report | T60: 0 | V60: Grey | Z60: =IF(Y60<>"",Y60-L60,IF(X60<>"",X60-L60,""))
A61: M3 | B61: WAVE 1 (5 APPS - LOW COMPLEXITY, INDEPENDENT) | C61: W1-11 | D61: Cutover & Hypercare | E61: Wave 1 performance validation and wave closure (Sev-1/2 closed) | F61: TPM / SRE | G61: Task | H61: 13 | I61: 1 | J61: 13 | K61: 46391 | L61: 46395 | M61: W1-09 | N61: W1-09 | O61: FS | P61: No | R61: Not Started | S61: Closure checklist | T61: 0 | V61: Grey | Z61: =IF(Y61<>"",Y61-L61,IF(X61<>"",X61-L61,""))
A62: M3 | B62: WAVE 1 (5 APPS - LOW COMPLEXITY, INDEPENDENT) | C62: GATE-M3 | D62: Program Management | E62: M3: WAVE 1 COMPLETE | F62: Steering Committee (proposed) | G62: Gate | H62: 13 | I62: 1 | J62: 13 | K62: 46391 | L62: 46395 | M62: W1-10, W1-11 | N62: W1-11 | O62: FS | P62: Yes | R62: Not Started | S62: Gate approval | T62: 0 | V62: Grey | Z62: =IF(Y62<>"",Y62-L62,IF(X62<>"",X62-L62,""))
A63: M4 | B63: WAVE 1 (5 APPS - LOW COMPLEXITY, INDEPENDENT) | C63: W1-12 | D63: Platform Foundation | E63: Wave 1 legacy shutdown (read-only retention) | F63: Platform / App Teams | G63: Task | H63: 14 | I63: 2 | J63: 15 | K63: 46398 | L63: 46409 | M63: GATE-M3 | N63: GATE-M3 | O63: FS | P63: No | R63: Not Started | S63: Legacy workloads stopped | T63: 0 | V63: Grey | Z63: =IF(Y63<>"",Y63-L63,IF(X63<>"",X63-L63,""))
A64: M2 | B64: WAVE 2 (6 APPS - COMPLEX, SHARED DATABASES, LEGACY WORKLOADS) | C64: W2-01 | D64: Application Migration | E64: Deep-dive: shared-DB groups (SDB-A/B/C), integration contracts, cutover grouping | F64: Cloud Architects / DBA | G64: Task | H64: 5 | I64: 3 | J64: 7 | K64: 46335 | L64: 46353 | M64: DS-09 | N64: DS-09 | O64: FS | P64: No | R64: Not Started | S64: Cutover grouping approved | T64: 0 | V64: Grey | Z64: =IF(Y64<>"",Y64-L64,IF(X64<>"",X64-L64,""))
A65: M2 | B65: WAVE 2 (6 APPS - COMPLEX, SHARED DATABASES, LEGACY WORKLOADS) | C65: W2-02 | D65: Application Migration | E65: Containerise / limited refactor of 4 apps (2 Refactor, 2 Replatform) | F65: App Teams | G65: Task | H65: 6 | I65: 4 | J65: 9 | K65: 46342 | L65: 46367 | M65: W2-01 | N65: W2-01 | O65: SS | P65: No | R65: Not Started | S65: Images and pipelines | T65: 0 | V65: Grey | Z65: =IF(Y65<>"",Y65-L65,IF(X65<>"",X65-L65,""))
A66: M2 | B66: WAVE 2 (6 APPS - COMPLEX, SHARED DATABASES, LEGACY WORKLOADS) | C66: W2-03 | D66: Application Migration | E66: Rehost 2 legacy .NET apps to GCE Windows VMs | F66: App Teams / Platform | G66: Task | H66: 7 | I66: 3 | J66: 9 | K66: 46349 | L66: 46367 | M66: W2-01 | N66: W2-01 | O66: FS | P66: No | R66: Not Started | S66: Rehosted apps in non-prod | T66: 0 | V66: Grey | Z66: =IF(Y66<>"",Y66-L66,IF(X66<>"",X66-L66,""))
A67: M2-M3 | B67: WAVE 2 (6 APPS - COMPLEX, SHARED DATABASES, LEGACY WORKLOADS) | C67: W2-04 | D67: Application Migration | E67: Deploy to non-prod and integration environments (shared-DB test) | F67: Platform Lead | G67: Task | H67: 9 | I67: 2 | J67: 10 | K67: 46363 | L67: 46374 | M67: W2-02 | N67: W2-02 | O67: FS | P67: No | R67: Not Started | S67: Integrated test environment | T67: 0 | V67: Grey | Z67: =IF(Y67<>"",Y67-L67,IF(X67<>"",X67-L67,""))
A68: M2-M3 | B68: WAVE 2 (6 APPS - COMPLEX, SHARED DATABASES, LEGACY WORKLOADS) | C68: W2-05 | D68: Database Migration | E68: Shared-DB replication and initial load (largest DBs); throughput and lag monitoring | F68: DBA Lead | G68: Task | H68: 9 | I68: 5 | J68: 13 | K68: 46363 | L68: 46395 | M68: GATE-M2 | N68: GATE-M2 | O68: FS | P68: Yes | R68: Not Started | S68: Replicating shared DBs | T68: 0 | V68: Grey | Z68: =IF(Y68<>"",Y68-L68,IF(X68<>"",X68-L68,""))
...

Sheet Application Tracker
A1: Application Migration Tracker
A3: App ID | B3: Application | C3: Runtime | D3: Workload Type | E3: Tier | F3: Wave | G3: Disposition | H3: Source Platform | I3: DB Size (TB) | J3: Shared DB Group | K3: Cutover Window | L3: Cutover Week | M3: Cutover Date | N3: Key Dependencies / Notes | O3: Current Status
A4: App-01 | B4: App-01 [rename] | C4: .NET | D4: Web | E4: 3 | F4: Pilot | G4: Replatform | H4: Legacy A | I4: 0.5 | K4: Pilot | L4: 7 | M4: 46349 | N4: Pilot .NET app; validates Windows-container path and IIS/auth handling | O4: Not Started
A5: App-02 | B5: App-02 [rename] | C5: Java | D5: API | E5: 3 | F5: Pilot | G5: Replatform | H5: Legacy B | I5: 0.8 | K5: Pilot | L5: 7 | M5: 46349 | N5: Pilot Java app; validates JVM container baseline and DB replication | O5: Not Started
A6: App-03 | B6: App-03 [rename] | C6: Java | D6: Batch | E6: 3 | F6: Pilot | G6: Replatform | H6: Legacy A | I6: 0.4 | K6: Pilot | L6: 7 | M6: 46349 | N6: Pilot batch app; validates scheduler integration and job re-runs | O6: Not Started
A7: App-04 | B7: App-04 [rename] | C7: .NET | D7: Web | E7: 3 | F7: Wave 1 | G7: Replatform | H7: Legacy B | I7: 1 | K7: W1 | L7: 10 | M7: 46370 | N7: Independent; internal users | O7: Not Started
A8: App-05 | B8: App-05 [rename] | C8: .NET | D8: API | E8: 2 | F8: Wave 1 | G8: Replatform | H8: Legacy A | I8: 1.5 | K8: W1 | L8: 10 | M8: 46370 | N8: Independent API; confirm consumer list in discovery | O8: Not Started
A9: App-06 | B9: App-06 [rename] | C9: Java | D9: API | E9: 3 | F9: Wave 1 | G9: Replatform | H9: Legacy B | I9: 0.8 | K9: W1 | L9: 10 | M9: 46370 | N9: Independent service | O9: Not Started
A10: App-07 | B10: App-07 [rename] | C10: Java | D10: Web | E10: 3 | F10: Wave 1 | G10: Replatform | H10: Legacy A | I10: 0.6 | K10: W1 | L10: 10 | M10: 46370 | N10: Independent; SSO integration | O10: Not Started
A11: App-08 | B11: App-08 [rename] | C11: Java | D11: Batch | E11: 3 | F11: Wave 1 | G11: Replatform | H11: Legacy B | I11: 0.9 | K11: W1 | L11: 10 | M11: 46370 | N11: Batch; scheduler / file-drop dependencies | O11: Not Started
A12: App-09 | B12: App-09 [rename] | C12: .NET | D12: Web | E12: 2 | F12: Wave 2 | G12: Rehost | H12: Legacy A | I12: 4 | J12: SDB-A | K12: W2a | L12: 14 | M12: 46398 | N12: Legacy .NET Framework; shares DB with App-10; GCE Windows VM | O12: Not Started
A13: App-10 | B13: App-10 [rename] | C13: .NET | D13: API | E13: 2 | F13: Wave 2 | G13: Rehost | H13: Legacy A | I13: 0 | J13: SDB-A | K13: W2a | L13: 14 | M13: 46398 | N13: Shares SDB-A with App-09 - must cut over together | O13: Not Started
A14: App-11 | B14: App-11 [rename] | C14: Java | D14: Web | E14: 2 | F14: Wave 2 | G14: Refactor | H14: Legacy B | I14: 3.5 | J14: SDB-B | K14: W2a | L14: 14 | M14: 46398 | N14: Shares DB with App-12; limited refactor to decouple | O14: Not Started
A15: App-12 | B15: App-12 [rename] | C15: Java | D15: API | E15: 2 | F15: Wave 2 | G15: Replatform | H15: Legacy B | I15: 0 | J15: SDB-B | K15: W2a | L15: 14 | M15: 46398 | N15: Shares SDB-B with App-11 | O15: Not Started
A16: App-13 | B16: App-13 [rename] | C16: .NET | D16: Web | E16: 1 | F16: Wave 2 | G16: Refactor | H16: Legacy A | I16: 6 | J16: SDB-C | K16: W2b | L16: 15 | M16: 46405 | N16: Revenue-critical; shares DB with App-14; strict RTO / RPO | O16: Not Started
A17: App-14 | B17: App-14 [rename] | C17: .NET | D17: API | E17: 1 | F17: Wave 2 | G17: Replatform | H17: Legacy B | I17: 0 | J17: SDB-C | K17: W2b | L17: 15 | M17: 46405 | N17: Shares SDB-C with App-13; customer-facing | O17: Not Started
A18: App-15 | B18: App-15 [rename] | C18: Java | D18: API | E18: 2 | F18: Wave 3 | G18: Replatform | H18: Legacy A | I18: 2.5 | K18: W3a | L18: 18 | M18: 46426 | N18: Depends on Wave 2 services - validate in coexistence | O18: Not Started
A19: App-16 | B19: App-16 [rename] | C19: .NET | D19: Web | E19: 2 | F19: Wave 3 | G19: Replatform | H19: Legacy B | I19: 3 | K19: W3a | L19: 18 | M19: 46426 | N19: Business-critical; third-party integrations | O19: Not Started
A20: App-17 | B20: App-17 [rename] | C20: Java | D20: Batch | E20: 2 | F20: Wave 3 | G20: Replatform | H20: Legacy A | I20: 1.5 | K20: W3a | L20: 18 | M20: 46426 | N20: Batch; month-end processing - avoid month-end cutover | O20: Not Started
A21: App-18 | B21: App-18 [rename] | C21: .NET | D21: Web | E21: 1 | F21: Wave 3 | G21: Replatform | H21: Legacy B | I21: 7.5 | K21: W3b | L21: 19 | M21: 46433 | N21: Tier 1; largest DB; peak-load testing mandatory | O21: Not Started
A22: App-19 | B22: App-19 [rename] | C22: Java | D22: API | E22: 1 | F22: Wave 3 | G22: Refactor | H22: Legacy A | I22: 4 | K22: W3b | L22: 19 | M22: 46433 | N22: Tier 1; refactor for HA; partner traffic | O22: Not Started
A23: App-20 | B23: App-20 [rename] | C23: .NET | D23: Web | E23: 1 | F23: Wave 3 | G23: Replatform | H23: Legacy B | I23: 5 | K23: W3b | L23: 19 | M23: 46433 | N23: Tier 1; customer-facing; vendor IP allow-listing | O23: Not Started

Sheet Gate Readiness
A1: Milestone & Gate Readiness
A3: Gate ID | B3: Gate / Decision Point | C3: Target Week | D3: Target Date | E3: Approver | F3: # Criteria | G3: # Complete | H3: Readiness % | I3: RAG | J3: Decision / Notes
A4: GATE-M1 | B4: M1: FOUNDATION READY | C4: 4 | D4: 46328 | E4: Security + Platform | F4: =COUNTIF('Gate Criteria Checklist'!$A:$A,A4) -> 10 | G4: =COUNTIFS('Gate Criteria Checklist'!$A:$A,A4,'Gate Criteria Checklist'!$F:$F,"Complete") -> 0 | H4: =IF(F4=0,0,G4/F4) -> 0 | I4: =IF(F4=0,"No Criteria",IF(G4=0,"Not Started",IF(H4=1,"Green",IF(H4>=0.75,"Amber","Red")))) -> Not Started
A5: GATE-PILOT | B5: PILOT GO-LIVE APPROVAL + CAB | C5: 6 | D5: 46346 | E5: Steering Committee / CAB | F5: =COUNTIF('Gate Criteria Checklist'!$A:$A,A5) -> 6 | G5: =COUNTIFS('Gate Criteria Checklist'!$A:$A,A5,'Gate Criteria Checklist'!$F:$F,"Complete") -> 0 | H5: =IF(F5=0,0,G5/F5) -> 0 | I5: =IF(F5=0,"No Criteria",IF(G5=0,"Not Started",IF(H5=1,"Green",IF(H5>=0.75,"Amber","Red")))) -> Not Started
A6: GATE-M2 | B6: M2: PILOT PROVEN | C6: 9 | D6: 46367 | E6: Steering Committee | F6: =COUNTIF('Gate Criteria Checklist'!$A:$A,A6) -> 8 | G6: =COUNTIFS('Gate Criteria Checklist'!$A:$A,A6,'Gate Criteria Checklist'!$F:$F,"Complete") -> 0 | H6: =IF(F6=0,0,G6/F6) -> 0 | I6: =IF(F6=0,"No Criteria",IF(G6=0,"Not Started",IF(H6=1,"Green",IF(H6>=0.75,"Amber","Red")))) -> Not Started
A7: GATE-W1-GO | B7: WAVE 1 GO / NO-GO + CAB | C7: 9 | D7: 46367 | E7: CAB | F7: =COUNTIF('Gate Criteria Checklist'!$A:$A,A7) -> 8 | G7: =COUNTIFS('Gate Criteria Checklist'!$A:$A,A7,'Gate Criteria Checklist'!$F:$F,"Complete") -> 0 | H7: =IF(F7=0,0,G7/F7) -> 0 | I7: =IF(F7=0,"No Criteria",IF(G7=0,"Not Started",IF(H7=1,"Green",IF(H7>=0.75,"Amber","Red")))) -> Not Started
A8: GATE-M3 | B8: M3: WAVE 1 COMPLETE | C8: 13 | D8: 46395 | E8: Steering Committee | F8: =COUNTIF('Gate Criteria Checklist'!$A:$A,A8) -> 7 | G8: =COUNTIFS('Gate Criteria Checklist'!$A:$A,A8,'Gate Criteria Checklist'!$F:$F,"Complete") -> 0 | H8: =IF(F8=0,0,G8/F8) -> 0 | I8: =IF(F8=0,"No Criteria",IF(G8=0,"Not Started",IF(H8=1,"Green",IF(H8>=0.75,"Amber","Red")))) -> Not Started
A9: GATE-W2-GO | B9: WAVE 2 GO / NO-GO + CAB | C9: 13 | D9: 46395 | E9: CAB | F9: =COUNTIF('Gate Criteria Checklist'!$A:$A,A9) -> 8 | G9: =COUNTIFS('Gate Criteria Checklist'!$A:$A,A9,'Gate Criteria Checklist'!$F:$F,"Complete") -> 0 | H9: =IF(F9=0,0,G9/F9) -> 0 | I9: =IF(F9=0,"No Criteria",IF(G9=0,"Not Started",IF(H9=1,"Green",IF(H9>=0.75,"Amber","Red")))) -> Not Started
A10: GATE-M4 | B10: M4: WAVE 2 COMPLETE | C10: 17 | D10: 46423 | E10: Steering Committee | F10: =COUNTIF('Gate Criteria Checklist'!$A:$A,A10) -> 7 | G10: =COUNTIFS('Gate Criteria Checklist'!$A:$A,A10,'Gate Criteria Checklist'!$F:$F,"Complete") -> 0 | H10: =IF(F10=0,0,G10/F10) -> 0 | I10: =IF(F10=0,"No Criteria",IF(G10=0,"Not Started",IF(H10=1,"Green",IF(H10>=0.75,"Amber","Red")))) -> Not Started
A11: GATE-W3-GO | B11: WAVE 3 GO / NO-GO + CAB | C11: 17 | D11: 46423 | E11: CAB | F11: =COUNTIF('Gate Criteria Checklist'!$A:$A,A11) -> 8 | G11: =COUNTIFS('Gate Criteria Checklist'!$A:$A,A11,'Gate Criteria Checklist'!$F:$F,"Complete") -> 0 | H11: =IF(F11=0,0,G11/F11) -> 0 | I11: =IF(F11=0,"No Criteria",IF(G11=0,"Not Started",IF(H11=1,"Green",IF(H11>=0.75,"Amber","Red")))) -> Not Started
A12: GATE-M5 | B12: M5: WAVE 3 COMPLETE | C12: 21 | D12: 46451 | E12: Steering Committee | F12: =COUNTIF('Gate Criteria Checklist'!$A:$A,A12) -> 7 | G12: =COUNTIFS('Gate Criteria Checklist'!$A:$A,A12,'Gate Criteria Checklist'!$F:$F,"Complete") -> 0 | H12: =IF(F12=0,0,G12/F12) -> 0 | I12: =IF(F12=0,"No Criteria",IF(G12=0,"Not Started",IF(H12=1,"Green",IF(H12>=0.75,"Amber","Red")))) -> Not Started
A13: GATE-DR | B13: DR VALIDATION SIGN-OFF | C13: 24 | D13: 46472 | E13: Infrastructure Leadership | F13: =COUNTIF('Gate Criteria Checklist'!$A:$A,A13) -> 6 | G13: =COUNTIFS('Gate Criteria Checklist'!$A:$A,A13,'Gate Criteria Checklist'!$F:$F,"Complete") -> 0 | H13: =IF(F13=0,0,G13/F13) -> 0 | I13: =IF(F13=0,"No Criteria",IF(G13=0,"Not Started",IF(H13=1,"Green",IF(H13>=0.75,"Amber","Red")))) -> Not Started
A14: GATE-DECOM | B14: LEGACY DECOMMISSION APPROVAL | C14: 24 | D14: 46472 | E14: Executive Sponsor | F14: =COUNTIF('Gate Criteria Checklist'!$A:$A,A14) -> 6 | G14: =COUNTIFS('Gate Criteria Checklist'!$A:$A,A14,'Gate Criteria Checklist'!$F:$F,"Complete") -> 0 | H14: =IF(F14=0,0,G14/F14) -> 0 | I14: =IF(F14=0,"No Criteria",IF(G14=0,"Not Started",IF(H14=1,"Green",IF(H14>=0.75,"Amber","Red")))) -> Not Started
A15: GATE-M6 | B15: M6: MIGRATION COMPLETE | C15: 26 | D15: 46486 | E15: Executive Sponsor / SteerCo | F15: =COUNTIF('Gate Criteria Checklist'!$A:$A,A15) -> 7 | G15: =COUNTIFS('Gate Criteria Checklist'!$A:$A,A15,'Gate Criteria Checklist'!$F:$F,"Complete") -> 0 | H15: =IF(F15=0,0,G15/F15) -> 0 | I15: =IF(F15=0,"No Criteria",IF(G15=0,"Not Started",IF(H15=1,"Green",IF(H15>=0.75,"Amber","Red")))) -> Not Started
A17: RAG Logic
A18: Not Started | B18: 0 criteria complete
A19: Red | B19: 1%-74% complete
A20: Amber | B20: 75%-99% complete
A21: Green | B21: 100% complete

Sheet Gate Criteria Checklist
A1: Gate Exit-Criteria Checklist
A2: Update only the Status column. Gate Readiness calculates automatically from this checklist.
A4: Gate ID | B4: Exit Criterion | C4: Owner | D4: Evidence / Artefact | E4: Source | F4: Status | G4: Comments / Evidence Link
A5: GATE-M1 | B5: Landing zone approved | C5: Platform Lead | D5: Architecture review record | E5: Plan | F5: Not Started
A6: GATE-M1 | B6: Security sign-off obtained | C6: Security Lead | D6: Signed assessment; pen-test closure | E6: Plan | F6: Not Started
A7: GATE-M1 | B7: Application inventory completed | C7: TPM | D7: Inventory reconciled with CMDB (20 apps) | E7: Plan | F7: Not Started
A8: GATE-M1 | B8: Dependency map completed | C8: TPM | D8: Dependency map; shared-DB groups | E8: Plan | F8: Not Started
A9: GATE-M1 | B9: Wave plan approved | C9: TPM | D9: Wave plan signed by SteerCo | E9: Plan | F9: Not Started
A10: GATE-M1 | B10: Hybrid connectivity tested at required bandwidth | C10: Platform Lead | D10: Throughput test report | E10: Added | F10: Not Started
A11: GATE-M1 | B11: Target architecture decisions approved (compute, PostgreSQL service, DR topology) | C11: Cloud Architects | D11: Signed ADRs | E11: Added | F11: Not Started
A12: GATE-M1 | B12: Change calendar, freeze windows and CAB slots agreed | C12: Change Manager | D12: Published calendar | E12: Added | F12: Not Started
A13: GATE-M1 | B13: Compliance control mapping and evidence process accepted | C13: Security Lead | D13: Control matrix | E13: Added | F13: Not Started
A14: GATE-M1 | B14: Managed PostgreSQL HA / PITR / cross-region replica pattern proven in sandbox | C14: DBA Lead | D14: Test record | E14: Added | F14: Not Started
A15: GATE-PILOT | B15: Functional, regression, performance and security tests complete | C15: QA Lead | D15: Test summary report | E15: Plan | F15: Not Started
A16: GATE-PILOT | B16: Data validation: counts and checksums reconcile 100% | C16: DBA Lead | D16: Reconciliation report | E16: Plan | F16: Not Started
... A92: GATE-M6 | B92: Budget variance reported and closed | C92: Finance | D92: Final cost report | E92: Added | F92: Not Started

Sheet Critical Dependencies
A1: Dependency Register
A3: ID | B3: Category | C3: Dependency | D3: Provider / Owner | E3: Blocks Task ID | F3: Blocked Task | G3: Needed-by Wk | H3: Needed-by Date | I3: Lead Time (wks) | J3: Latest Start Wk | K3: Latest Start Date | L3: Urgency | M3: Waves Affected | N3: Mitigation / Action | O3: Status | P3: RAG
A4: D-01 | B4: Technical | C4: Hybrid connectivity (Dedicated/Partner Interconnect + HA VPN backup) sized for tens-of-TB replication; carrier circuit and cross-connect provisioning | D4: Platform Lead / Network / Carrier | E4: LZ-09 | F4: Data-migration tooling and replication pipeline; throughput test over hybrid link | G4: 3 | H4: 46321 | I4: 6 | J4: -3 | K4: 46279 | L4: START AT KICKOFF | M4: All | N4: Order circuits at kickoff; stand up HA VPN as interim path; size for peak concurrent replication (Wave 2 + 3); fallback: offline transfer appliance for initial seed | O4: Not Started | P4: Red
A5: D-02 | B5: Technical | C5: Identity: SSO / IdP federation, service accounts, Kerberos / Windows-integrated auth for .NET apps across GCP and legacy | D5: Identity team / Security | E5: PL-03 | F5: Deploy to GCP non-prod; secrets/config onboarding; observability wiring | G5: 5 | H5: 46335 | I5: 3 | J5: 2 | K5: 46314 | L5: START IN MONTH 1 | M5: All (.NET esp.) | N5: Design in DS-07; test in pilot .NET app; keep AD trust path during coexistence | O5: Not Started | P5: Amber
A6: D-03 | B6: Technical | C6: Shared databases between apps (SDB-A / B / C) - apps must cut over together or be decoupled first | D6: DBA Lead / App Teams | E6: W2-05 | F6: Shared-DB replication and initial load (largest DBs); throughput and lag monitoring | G6: 9 | H6: 46363 | I6: 5 | J6: 4 | K6: 46328 | L6: START IN MONTH 1 | M6: Wave 2 | N6: Group apps by DB for cutover; decouple via APIs where cheap; rehearse group cutover twice | O6: Not Started | P6: Red
A7: D-04 | B7: Technical | C7: Middleware / message queues reachable from GCP while apps are split across platforms | D7: Middleware team | E7: W2-04 | F7: Deploy to non-prod and integration environments (shared-DB test) | G7: 9 | H7: 46363 | I7: 4 | J7: 5 | K7: 46335 | M7: Waves 1-3 | N7: Network path + firewall rules before non-prod; confirm MQ licensing / cloud support | O7: Not Started | P7: Amber
A8: D-05 | B8: Technical | C8: File transfers (SFTP / MFT) - partner endpoints, keys and schedules must be re-pointed | D8: Integration team / App Teams | E8: W2-10 | F8: CUTOVER 2a: shared-DB groups SDB-A and SDB-B (4 Tier-2 apps) | G8: 14 | H8: 46398 | I8: 6 | J8: 8 | K8: 46356 | M8: Waves 1-3 | N8: Inventory all inbound/outbound transfers in DS-03; agree partner change windows early | O8: Not Started | P8: Amber
A9: D-06 | B9: Technical | C9: Internal API coexistence - chatty calls between GCP and legacy add latency during split state | D9: Cloud Architects | E9: W2-04 | F9: Deploy to non-prod and integration environments (shared-DB test) | G9: 9 | H9: 46363 | I9: 3 | J9: 6 | K9: 46342 | M9: Waves 2-3 | N9: Keep chatty apps in the same wave; measure latency in non-prod; use caching / batching where needed | O9: Not Started | P9: Amber
A10: D-07 | B10: Technical | C10: DNS, load-balancer and certificate (PKI) cutover; lower TTLs 48-72h before each cutover | D10: Network / Platform | E10: W1-08 | F10: WAVE 1 PRODUCTION CUTOVER (5 apps) - before year-end freeze | G10: 10 | H10: 46370 | I10: 3 | J10: 7 | K10: 46349 | M10: All | N10: Standard pre-cutover checklist maintained in the approved cutover runbook; test certificate chain in non-prod | O10: Not Started | P10: Green
A11: D-08 | B11: Technical | C11: PostgreSQL version / extension / role compatibility with the chosen managed service; storage limits vs largest DBs | D11: DBA Lead | E11: LZ-08 | F11: Managed PostgreSQL pattern: HA, automated backup, PITR, cross-region replica, CMEK | G11: 2 | H11: 46314 | I11: 2 | J11: 0 | K11: 46300 | L11: START AT KICKOFF | M11: All DB moves | N11: DS-04 profiling; compatibility test in sandbox; fall back to self-managed PostgreSQL for exceptions | O11: Not Started | P11: Amber
A12: D-09 | B12: Technical | C12: Secrets, keys and certificates migration (CMEK/KMS, HSM-backed keys where required) | D12: Security Lead | E12: LZ-04 | F12: Security controls: CMEK/KMS, secrets management, SIEM logging, vulnerability scanning | G12: 2 | H12: 46314 | I12: 2 | J12: 0 | K12: 46300 | L12: START AT KICKOFF | M12: All | N12: Secrets inventory in discovery; no secrets in images; rotate at cutover | O12: Not Started | P12: Amber
A13: D-10 | B13: Technical | C13: Integration with enterprise SIEM, ITSM and monitoring tools | D13: SRE / Security | E13: LZ-05 | F13: Observability: monitoring, logging, tracing, alerting, SLO dashboards | G13: 2 | H13: 46314 | I13: 1 | J13: 1 | K13: 46307 | L13: START AT KICKOFF | M13: All | N13: Agree log/metric export design in DS-07; test alert routing in pilot | O13: Not Started | P13: Green
A14: D-11 | B14: Technical | C14: Masked, prod-like test data available for non-prod testing | D14: QA Lead / DBA Lead | E14: PL-05 | F14: Functional and regression testing (incl. batch scheduling) | G14: 5 | H14: 46335 | I14: 3 | J14: 2 | K14: 46314 | L14: START IN MONTH 1 | M14: All | N14: Data-masking pipeline built with LZ-09; privacy sign-off | O14: Not Started | P14: Amber
A15: D-12 | B15: Technical | C15: Batch scheduler integration (job dependencies, calendars, re-run behaviour) | D15: App Teams / Ops | E15: PL-03 | F15: Deploy to GCP non-prod; secrets/config onboarding; observability wiring | G15: 5 | H15: 46335 | I15: 3 | J15: 2 | K15: 46314 | L15: START IN MONTH 1 | M15: Pilot, W1, W3 | N15: Pilot batch app proves the pattern; document re-run/restart procedures | O15: Not Started | P15: Amber
A16: D-13 | B16: Technical | C16: Windows licensing and Windows-node support for .NET Framework workloads (containers or GCE) | D16: Platform Lead / Procurement | E16: LZ-06 | F16: Compute platform build (per ADR), registry, Windows node pool if required | G16: 2 | H16: 46314 | I16: 2 | J16: 0 | K16: 46300 | L16: START AT KICKOFF | M16: Wave 2 | N16: Decide container vs VM in DS-06; confirm licence mobility early | O16: Not Started | P16: Amber
A17: D-14 | B17: Organizational | C17: Security sign-off of the landing zone (pen-test, control mapping) | D17: Security Lead | E17: GATE-M1 | F17: M1: FOUNDATION READY (approver: Security + Platform) | G17: 4 | H17: 46328 | I17: 4 | J17: 0 | K17: 46300 | L17: START AT KICKOFF | M17: All | N17: Security engineer embedded in platform team; weekly security review; pre-agreed patterns | O17: Not Started | P17: Amber
A18: D-15 | B18: Organizational | C18: GCP quotas (vCPU, IPs, DB instances) raised ahead of peak waves | D18: Platform Lead / Google TAM | E18: W2-04 | F18: Deploy to non-prod and integration environments (shared-DB test) | G18: 9 | H18: 46363 | I18: 4 | J18: 5 | K18: 46335 | M18: Waves 2-3 | N18: Request quota increases at M1 and again before Wave 2 and Wave 3 non-prod | O18: Not Started | P18: Green
A19: D-16 | B19: Organizational | C19: CAB slots and change-freeze calendar for every production cutover | D19: Change Manager | E19: PL-08 | F19: PILOT PRODUCTION CUTOVER (3 apps) | G19: 7 | H19: 46349 | I19: 4 | J19: 3 | K19: 46321 | L19: START IN MONTH 1 | M19: All | N19: Book all cutover slots in PM-04; check Freeze Check column on Roadmap | O19: Not Started | P19: Amber
A20: D-17 | B20: Organizational | C20: Environment provisioning requests through ITSM (non-prod, UAT, access) | D20: Platform Lead | E20: PL-03 | F20: Deploy to GCP non-prod; secrets/config onboarding; observability wiring | G20: 5 | H20: 46335 | I20: 3 | J20: 2 | K20: 46314 | L20: START IN MONTH 1 | M20: All | N20: Pre-raise requests for every wave in PM-03; use IaC for self-service | O20: Not Started | P20: Amber
A21: D-18 | B21: Organizational | C21: SME backfill - application SMEs and DBAs released from BAU | D21: App Owners / Hiring managers | E21: W2-02 | F21: Containerise / limited refactor of 4 apps (2 Refactor, 2 Replatform) | G21: 6 | H21: 46342 | I21: 6 | J21: 0 | K21: 46300 | L21: START AT KICKOFF | M21: Waves 2-3 | N21: Backfill approved in PM-03; resource loading reviewed monthly | O21: Not Started | P21: Red
A22: D-19 | B22: Organizational | C22: Business UAT availability and sign-off (esp. Tier 1) | D22: Business owners / Change Manager | E22: W1-04 | F22: Functional, regression, performance and security testing | G22: 6 | H22: 46342 | I22: 4 | J22: 2 | K22: 46314 | L22: START IN MONTH 1 | M22: All | N22: UAT windows booked at wave plan approval; delegate approvers named | O22: Not Started | P22: Amber
A23: D-20 | B23: Organizational | C23: Funding release, billing account and GCP commitment in place | D23: Finance / Executive Sponsor | E23: LZ-01 | F23: Org hierarchy, projects/folders, org policies, billing and budget alerts | G23: 1 | H23: 46307 | I23: 2 | J23: -1 | K23: 46293 | L23: START AT KICKOFF | M23: All | N23: Confirm at kickoff (assumption in program plan) | O23: Not Started | P23: Green
A24: D-21 | B24: Organizational | C24: Third-party / vendor-risk assessment of GCP services in scope | D24: Compliance / Procurement | E24: GATE-M1 | F24: M1: FOUNDATION READY (approver: Security + Platform) | G24: 4 | H24: 46328 | I24: 6 | J24: -2 | K24: 46286 | L24: START AT KICKOFF | M24: All | N24: Start at kickoff; reuse existing cloud risk assessments where possible | O24: Not Started | P24: Amber
A25: D-22 | B25: Organizational | C25: SRE training and on-call onboarding for new platform | D25: SRE Lead | E25: FN-04 | F25: SRE handoff: runbook validation, on-call readiness, support model, incident process | G25: 22 | H25: 46454 | I25: 8 | J25: 14 | K25: 46398 | M25: All | N25: SRE engaged from Month 1; shadow on-call from pilot | O25: Not Started | P25: Green
A26: D-23 | B26: Organizational | C26: Pilot gate (M2) approved before any wave production cutover (Non-negotiable #2) | D26: Steering Committee | E26: W1-08 | F26: WAVE 1 PRODUCTION CUTOVER (5 apps) - before year-end freeze | G26: 10 | H26: 46370 | I26: 0 | J26: 10 | K26: 46370 | M26: Waves 1-3 | N26: Pilot go/no-go criteria agreed at M1; retro feeds Wave 1 runbooks | O26: Not Started | P26: Green
A27: D-24 | B27: External | C27: Third-party vendors / partners must allow-list new GCP egress IPs and accept changed endpoints | D27: Vendor Management | E27: W1-08 | F27: WAVE 1 PRODUCTION CUTOVER (5 apps) - before year-end freeze | G27: 10 | H27: 46370 | I27: 6 | J27: 4 | K27: 46328 | L27: START IN MONTH 1 | M27: All | N27: Reserve static egress IPs early; send change notices at wave plan approval | O27: Not Started | P27: Amber
A28: D-25 | B28: External | C28: Regulatory notification / approval for material cloud outsourcing (as applicable to your regulator) | D28: Compliance / Legal | E28: GATE-PILOT | F28: PILOT GO-LIVE approval (approver: Steering Committee) + CAB | G28: 6 | H28: 46342 | I28: 8 | J28: -2 | K28: 46286 | L28: START AT KICKOFF | M28: All | N28: Confirm obligations at kickoff (PM-05); start any pre-notification immediately | O28: Not Started | P28: Red
A29: D-26 | B29: External | C29: Google Cloud account team: support tier, TAM, quota escalations, architecture review | D29: Vendor Management | E29: LZ-01 | F29: Org hierarchy, projects/folders, org policies, billing and budget alerts | G29: 1 | H29: 46307 | I29: 2 | J29: -1 | K29: 46293 | L29: START AT KICKOFF | M29: All | N29: Engage at kickoff; named escalation contacts | O29: Not Started | P29: Green
A30: D-27 | B30: External | C30: Legacy platform contracts, leases and exit-notice periods (needed for decommission in Month 6) | D30: Procurement / Infrastructure | E30: FN-06 | F30: Decommission readiness review (zero traffic, no consumers, contract / lease notices) | G30: 23 | H30: 46461 | I30: 16 | J30: 7 | K30: 46349 | M30: All | N30: Review contracts in Month 1; serve notices when waves complete | O30: Not Started | P30: Red
A31: D-28 | B31: External | C31: ISV / third-party software licensing and cloud support statements | D31: Procurement | E31: W2-03 | F31: Rehost 2 legacy .NET apps to GCE Windows VMs | G31: 7 | H31: 46349 | I31: 4 | J31: 3 | K31: 46321 | L31: START IN MONTH 1 | M31: Wave 2 | N31: Inventory ISV components in DS-02; confirm supported on GCE / containers | O31: Not Started | P31: Amber
A32: D-29 | B32: External | C32: Customer / partner communications for Tier-1 downtime windows | D32: Business owners / Comms | E32: W3-11 | F32: CUTOVER 3b: Tier-1 apps (3 apps) - final production cutover | G32: 19 | H32: 46433 | I32: 6 | J32: 13 | K32: 46391 | M32: Wave 3 | N32: Agree notice periods in contracts; schedule outside business peaks | O32: Not Started | P32: Amber

Sheet RAID Register
A1: Top 15 Program Risks
A3: ID | B3: Category | C3: Risk | D3: Impact | E3: Linked Tasks | F3: Score | G3: RAG | H3: Mitigation | I3: Contingency | J3: Early Warning | K3: Owner | L3: Due Week | M3: Residual RAG | N3: Escalation Path | O3: Status
A4: R-01 | B4: Schedule | C4: Hidden / unmapped dependencies surface late | D4: Schedule delay; failed cutover; wave re-plan | E4: All waves; DS-03 | F4: 16 | G4: Red | H4: Discovery workshops; network-flow capture on legacy (>= 30 days); weekly Dependency Review Board; dependency freeze at wave plan approval | I4: Add coexistence connectivity; hold wave until dependency resolved | J4: > 2 new dependencies found per wave after plan lock | K4: TPM | L4: 4 | M4: Green | N4: Owner -> TPM -> Steering Committee -> Executive Sponsor | O4: Open
A5: R-05 | B5: Infrastructure | C5: Hybrid network capacity or provisioning delays | D5: Replication cannot keep pace; waves slip | E5: LZ-03, LZ-09; Waves 2-3 | F5: 16 | G5: Red | H5: Order circuits at kickoff; HA VPN interim; redundant paths; throttling plan; replication throughput test at W3-4 | I5: Offline transfer appliance for bulk seed; re-sequence large DBs | J5: Circuit delivery date slips beyond W4 | K5: Platform Lead | L5: 2 | M5: Amber | N5: Owner -> TPM -> Steering Committee -> Executive Sponsor | O5: Open
A6: R-07 | B6: Resource | C6: Resource constraints: SMEs, DBAs, SRE oversubscribed across overlapping waves | D6: Reduced throughput; quality shortcuts | E6: W9-W17 | F6: 16 | G6: Red | H6: Resource-loading plan per wave; backfill approved at kickoff; dedicated migration capacity; deputy / PMO analyst for TPM | I6: Re-sequence Wave 3 prep; defer non-critical refactors | J6: Utilisation > 90% for key roles; stand-ups reporting blocked on people | K6: TPM | L6: 3 | M6: Amber | N6: Owner -> TPM -> Steering Committee -> Executive Sponsor | O6: Open
A7: R-12 | B7: Technical | C7: Shared-DB coupling forces multi-app big-bang cutovers in Wave 2 | D7: Larger blast radius; harder rollback | E7: Wave 2 | F7: 16 | G7: Red | H7: Group cutovers by DB; split into 2a / 2b; decouple through APIs where cheap; 2 full rehearsals | I7: Postpone coupled apps to later window; extended rollback window | J7: Rehearsal #1 fails or exceeds window | K7: Cloud Architect / DBA Lead | L7: 3 | M7: Amber | N7: Owner -> TPM -> Steering Committee -> Executive Sponsor | O7: Open
A8: R-29 | B8: Technical | C8: Data volume back-loaded into Wave 3; replication seeding overlaps Wave 2 on the same hybrid link | D8: Replication cannot catch up; cutover delay | E8: W2-05, W3-04 | F8: 16 | G8: Red | H8: Start Wave 3 seeding for largest DBs as early as safe; schedule bandwidth; QoS on link; consider offline seed | I8: Delay 3b; split DB cutovers | J8: Replication lag trend > 10 min after seeding | K8: DBA Lead / Platform Lead | L8: 3 | M8: Amber | N8: Owner -> TPM -> Steering Committee -> Executive Sponsor | O8: Open
A9: R-03 | B9: Data | C9: Data loss or corruption during migration of tens of TB | D9: Customer / regulatory impact; program failure | E9: All DB moves | F9: 15 | G9: Red | H9: Continuous replication with lag monitoring; counts + checksums + reconciliation; 2 rehearsals; cutover only when lag < agreed threshold | I9: Roll back to legacy using reverse replication; restore from PITR | J9: Replication lag trend rising; reconciliation variance > 0 | K9: DBA Lead | L9: 4 | M9: Green | N9: Owner -> TPM -> Steering Committee -> Executive Sponsor | O9: Open
A10: R-09 | B10: Resilience | C10: DR targets not achieved (RPO <= 5 min, RTO <= 60 min, 99.95% availability) | D10: Program failure / M2, M6 not met | E10: PL-10; W*-DR tests; FN-01 | F10: 15 | G10: Red | H10: DR topology ADR at W2; DR tests in pilot and every wave; automate failover; measure RPO/RTO each test | I10: Upgrade DB tier / replication mode; add warm standby; re-test | J10: Measured RPO or RTO > 80% of target in any test | K10: SRE Lead / DBA Lead | L10: 4 | M10: Amber | N10: Owner -> TPM -> Steering Committee -> Executive Sponsor | O10: Open
A11: R-13 | B11: Technical | C11: Rollback after DB cutover is complex (data written in GCP) | D11: Extended outage; data divergence | E11: All cutovers | F11: 15 | G11: Red | H11: Define rollback policy and point of no return per wave (DEC-08); reverse replication; rollback rehearsal; time-boxed decisions | I11: Forward-fix with war-room authority; restore from PITR | J11: Rollback rehearsal exceeds RTO | K11: DBA Lead / SRE Lead | L11: 3 | M11: Amber | N11: Owner -> TPM -> Steering Committee -> Executive Sponsor | O11: Open
A12: R-02 | B12: Technical | C12: Legacy .NET Framework apps not container-compatible | D12: Migration delay; rework | E12: Wave 2 (rehost); DS-06 | F12: 12 | G12: Amber | H12: Early PoC (DS-06); 2 apps already planned as Rehost; Windows node pool / GCE fallback | I12: Rehost on GCE Windows VMs | J12: PoC fails or needs > 2 weeks of rework per app | K12: Cloud Architect | L12: 5 | M12: Green | N12: Owner -> TPM -> Steering Committee -> Executive Sponsor | O12: Open
A13: R-04 | B13: Technical | C13: PostgreSQL incompatible with managed service (version, extensions, privileges, storage limits) | D13: Redesign; delay; cost | E13: LZ-08; all DBs | F13: 12 | G13: Amber | H13: DS-04 profiling; compatibility test in sandbox; DB service ADR at W2 | I13: Self-managed PostgreSQL on GCE for exceptions; shard / archive large DBs | J13: Any unsupported extension in profiling output | K13: DBA Lead | L13: 3 | M13: Green | N13: Owner -> TPM -> Steering Committee -> Executive Sponsor | O13: Open
A14: R-06 | B14: Security | C14: Security approval delays / findings block landing zone or releases | D14: Release blockage; M1 slips | E14: GATE-M1; all waves | F14: 12 | G14: Amber | H14: Security embedded from Day 1; pre-approved patterns; weekly security review; findings triaged by severity | I14: Time-boxed exception process with compensating controls | J14: > 3 high findings open one week before M1 | K14: Security Lead | L14: 4 | M14: Green | N14: Owner -> TPM -> Steering Committee -> Executive Sponsor | O14: Open
A15: R-10 | B15: Schedule | C15: Year-end / quarter-end freezes and holidays compress cutover windows | D15: Cutover slips by 3-4 weeks; Month-3 milestone missed | E15: PL-08, W1-08, W2-10 | F15: 12 | G15: Amber | H15: Freeze calendar maintained in the program change calendar; Wave 1 cutover scheduled before freeze; hypercare spans the freeze | I15: Use cutover contingency week; move pilot cutover to Mon-Tue of W7 | J15: Any planned cutover or DR test overlaps an approved freeze window | K15: Change Manager | L15: 1 | M15: Green | N15: Owner -> TPM -> Steering Committee -> Executive Sponsor | O15: Open
... A18: R-15 | B18: Compliance | C18: Regulatory notification / approval delays or audit evidence gaps | D18: Go-live blocked; audit findings | E18: GATE-PILOT; FN-08 | F18: 12 | G18: Amber | H18: PM-05 regulatory plan at kickoff; evidence captured continuously (LZ-10); compliance in SteerCo | I18: Escalate to Executive Sponsor / Legal; adjust wave dates | J18: No regulator acknowledgement 6 weeks before Pilot Go-Live | K18: TPM / Compliance | L18: 2 | M18: Green | N18: Owner -> TPM -> Steering Committee -> Executive Sponsor | O18: Open
